Traceback (most recent call last):
  File "C:\Python311\Lib\site-packages\jupyter_cache\executors\utils.py", line 58, in single_nb_execution
    executenb(
  File "C:\Python311\Lib\site-packages\nbclient\client.py", line 1314, in execute
    return NotebookClient(nb=nb, resources=resources, km=km, **kwargs).execute()
           ^^^^^^^^^^^^^^^^^^^^^^^^^^^^^^^^^^^^^^^^^^^^^^^^^^^^^^^^^^^^^^^^^^^^^
  File "C:\Users\Waffle\AppData\Roaming\Python\Python311\site-packages\jupyter_core\utils\__init__.py", line 165, in wrapped
    return loop.run_until_complete(inner)
           ^^^^^^^^^^^^^^^^^^^^^^^^^^^^^^
  File "C:\Python311\Lib\asyncio\base_events.py", line 653, in run_until_complete
    return future.result()
           ^^^^^^^^^^^^^^^
  File "C:\Python311\Lib\site-packages\nbclient\client.py", line 709, in async_execute
    await self.async_execute_cell(
  File "C:\Python311\Lib\site-packages\nbclient\client.py", line 1062, in async_execute_cell
    await self._check_raise_for_error(cell, cell_index, exec_reply)
  File "C:\Python311\Lib\site-packages\nbclient\client.py", line 918, in _check_raise_for_error
    raise CellExecutionError.from_cell_and_msg(cell, exec_reply_content)
nbclient.exceptions.CellExecutionError: An error occurred while executing the following cell:
------------------
from scipy.stats import kruskal

hours = WindSpeed['Hora'].unique()
speed = [WindSpeed[WindSpeed['Hora'] == hour]['Velocidad'] for hour in hours]

stat, pval = kruskal(*speed)
print( f'Resultados de la prueba:\nEstadÃ­stico: {stat}\nP-Valor: {pval}' )
------------------


[1;31m---------------------------------------------------------------------------[0m
[1;31mKeyError[0m                                  Traceback (most recent call last)
File [1;32mC:\Python311\Lib\site-packages\pandas\core\indexes\base.py:3790[0m, in [0;36mIndex.get_loc[1;34m(self, key)[0m
[0;32m   3789[0m [38;5;28;01mtry[39;00m:
[1;32m-> 3790[0m     [38;5;28;01mreturn[39;00m [38;5;28;43mself[39;49m[38;5;241;43m.[39;49m[43m_engine[49m[38;5;241;43m.[39;49m[43mget_loc[49m[43m([49m[43mcasted_key[49m[43m)[49m
[0;32m   3791[0m [38;5;28;01mexcept[39;00m [38;5;167;01mKeyError[39;00m [38;5;28;01mas[39;00m err:

File [1;32mindex.pyx:152[0m, in [0;36mpandas._libs.index.IndexEngine.get_loc[1;34m()[0m

File [1;32mindex.pyx:181[0m, in [0;36mpandas._libs.index.IndexEngine.get_loc[1;34m()[0m

File [1;32mpandas\_libs\hashtable_class_helper.pxi:7080[0m, in [0;36mpandas._libs.hashtable.PyObjectHashTable.get_item[1;34m()[0m

File [1;32mpandas\_libs\hashtable_class_helper.pxi:7088[0m, in [0;36mpandas._libs.hashtable.PyObjectHashTable.get_item[1;34m()[0m

[1;31mKeyError[0m: 'Hora'

The above exception was the direct cause of the following exception:

[1;31mKeyError[0m                                  Traceback (most recent call last)
Cell [1;32mIn[7], line 3[0m
[0;32m      1[0m [38;5;28;01mfrom[39;00m [38;5;21;01mscipy[39;00m[38;5;21;01m.[39;00m[38;5;21;01mstats[39;00m [38;5;28;01mimport[39;00m kruskal
[1;32m----> 3[0m hours [38;5;241m=[39m [43mWindSpeed[49m[43m[[49m[38;5;124;43m'[39;49m[38;5;124;43mHora[39;49m[38;5;124;43m'[39;49m[43m][49m[38;5;241m.[39munique()
[0;32m      4[0m speed [38;5;241m=[39m [WindSpeed[WindSpeed[[38;5;124m'[39m[38;5;124mHora[39m[38;5;124m'[39m] [38;5;241m==[39m hour][[38;5;124m'[39m[38;5;124mVelocidad[39m[38;5;124m'[39m] [38;5;28;01mfor[39;00m hour [38;5;129;01min[39;00m hours]
[0;32m      6[0m stat, pval [38;5;241m=[39m kruskal([38;5;241m*[39mspeed)

File [1;32mC:\Python311\Lib\site-packages\pandas\core\frame.py:3893[0m, in [0;36mDataFrame.__getitem__[1;34m(self, key)[0m
[0;32m   3891[0m [38;5;28;01mif[39;00m [38;5;28mself[39m[38;5;241m.[39mcolumns[38;5;241m.[39mnlevels [38;5;241m>[39m [38;5;241m1[39m:
[0;32m   3892[0m     [38;5;28;01mreturn[39;00m [38;5;28mself[39m[38;5;241m.[39m_getitem_multilevel(key)
[1;32m-> 3893[0m indexer [38;5;241m=[39m [38;5;28;43mself[39;49m[38;5;241;43m.[39;49m[43mcolumns[49m[38;5;241;43m.[39;49m[43mget_loc[49m[43m([49m[43mkey[49m[43m)[49m
[0;32m   3894[0m [38;5;28;01mif[39;00m is_integer(indexer):
[0;32m   3895[0m     indexer [38;5;241m=[39m [indexer]

File [1;32mC:\Python311\Lib\site-packages\pandas\core\indexes\base.py:3797[0m, in [0;36mIndex.get_loc[1;34m(self, key)[0m
[0;32m   3792[0m     [38;5;28;01mif[39;00m [38;5;28misinstance[39m(casted_key, [38;5;28mslice[39m) [38;5;129;01mor[39;00m (
[0;32m   3793[0m         [38;5;28misinstance[39m(casted_key, abc[38;5;241m.[39mIterable)
[0;32m   3794[0m         [38;5;129;01mand[39;00m [38;5;28many[39m([38;5;28misinstance[39m(x, [38;5;28mslice[39m) [38;5;28;01mfor[39;00m x [38;5;129;01min[39;00m casted_key)
[0;32m   3795[0m     ):
[0;32m   3796[0m         [38;5;28;01mraise[39;00m InvalidIndexError(key)
[1;32m-> 3797[0m     [38;5;28;01mraise[39;00m [38;5;167;01mKeyError[39;00m(key) [38;5;28;01mfrom[39;00m [38;5;21;01merr[39;00m
[0;32m   3798[0m [38;5;28;01mexcept[39;00m [38;5;167;01mTypeError[39;00m:
[0;32m   3799[0m     [38;5;66;03m# If we have a listlike key, _check_indexing_error will raise[39;00m
[0;32m   3800[0m     [38;5;66;03m#  InvalidIndexError. Otherwise we fall through and re-raise[39;00m
[0;32m   3801[0m     [38;5;66;03m#  the TypeError.[39;00m
[0;32m   3802[0m     [38;5;28mself[39m[38;5;241m.[39m_check_indexing_error(key)

[1;31mKeyError[0m: 'Hora'

